2024-10-11 19:29:34,066 - root - WARNING - Start Product Analyzer...



2024-10-11 19:29:34,075 - hypercorn.error - INFO - Running on http://127.0.0.1:5000 (CTRL + C to quit)



2024-10-11 19:34:18,457 - root - WARNING - Start Product Analyzer...



2024-10-11 19:34:18,466 - hypercorn.error - INFO - Running on http://127.0.0.1:5000 (CTRL + C to quit)



2024-10-11 19:34:41,732 - hypercorn.error - ERROR - Error in ASGI Framework


Traceback (most recent call last):
  File "/home/kolo/Python_Projects/Product_Analyzer/venv/lib/python3.11/site-packages/hypercorn/asyncio/task_group.py", line 27, in _handle
    await app(scope, receive, send, sync_spawn, call_soon)
  File "/home/kolo/Python_Projects/Product_Analyzer/venv/lib/python3.11/site-packages/hypercorn/app_wrappers.py", line 34, in __call__
    await self.app(scope, receive, send)
  File "/home/kolo/Python_Projects/Product_Analyzer/venv/lib/python3.11/site-packages/quart/app.py", line 1667, in __call__
    await self.asgi_app(scope, receive, send)
  File "/home/kolo/Python_Projects/Product_Analyzer/venv/lib/python3.11/site-packages/quart/app.py", line 1693, in asgi_app
    await asgi_handler(receive, send)
  File "/home/kolo/Python_Projects/Product_Analyzer/venv/lib/python3.11/site-packages/quart/asgi.py", line 52, in __call__
    raise_task_exceptions(done)
  File "/home/kolo/Python_Projects/Product_Analyzer/venv/lib/python3.11/site-packages/quart/utils.py", line 180, in raise_task_exceptions
    raise task.exception()
  File "/home/kolo/Python_Projects/Product_Analyzer/venv/lib/python3.11/site-packages/quart/asgi.py", line 107, in handle_request
    await asyncio.wait_for(self._send_response(send, response), timeout=timeout)
  File "/usr/lib/python3.11/asyncio/tasks.py", line 479, in wait_for
    return fut.result()
           ^^^^^^^^^^^^
  File "/home/kolo/Python_Projects/Product_Analyzer/venv/lib/python3.11/site-packages/quart/asgi.py", line 134, in _send_response
    async for data in response_body:
  File "/home/kolo/Python_Projects/Product_Analyzer/app.py", line 20, in main_view
    yield jsonify({'data': f'step - {i}'})
          ^^^^^^^^^^^^^^^^^^^^^^^^^^^^^^^^
  File "/home/kolo/Python_Projects/Product_Analyzer/venv/lib/python3.11/site-packages/quart/json/__init__.py", line 45, in jsonify
    return current_app.json.response(*args, **kwargs)  # type: ignore
           ^^^^^^^^^^^^^^^^
  File "/home/kolo/Python_Projects/Product_Analyzer/venv/lib/python3.11/site-packages/werkzeug/local.py", line 318, in __get__
    obj = instance._get_current_object()
          ^^^^^^^^^^^^^^^^^^^^^^^^^^^^^^
  File "/home/kolo/Python_Projects/Product_Analyzer/venv/lib/python3.11/site-packages/werkzeug/local.py", line 519, in _get_current_object
    raise RuntimeError(unbound_message) from None
RuntimeError: Not within an app context
2024-10-11 19:56:25,679 - root - WARNING - Start Product Analyzer...



2024-10-11 19:56:25,688 - hypercorn.error - INFO - Running on http://127.0.0.1:5000 (CTRL + C to quit)



2024-10-11 19:56:57,314 - asyncio - WARNING - Executing <Task pending name='Task-24' coro=<ASGIHTTPConnection.handle_request() running at /home/kolo/Python_Projects/Product_Analyzer/venv/lib/python3.11/site-packages/quart/asgi.py:107> wait_for=<Future pending cb=[Task.task_wakeup()] created at /usr/lib/python3.11/asyncio/base_events.py:427> cb=[_wait.<locals>._on_completion() at /usr/lib/python3.11/asyncio/tasks.py:509] created at /usr/lib/python3.11/asyncio/tasks.py:670> took 3.924 seconds



2024-10-11 20:00:03,383 - root - WARNING - Start Product Analyzer...



2024-10-11 20:00:03,393 - hypercorn.error - INFO - Running on http://127.0.0.1:5000 (CTRL + C to quit)



2024-10-11 20:06:36,199 - root - WARNING - Start Product Analyzer...



2024-10-11 20:06:36,208 - hypercorn.error - INFO - Running on http://127.0.0.1:5000 (CTRL + C to quit)



2024-10-11 20:06:48,599 - hypercorn.error - ERROR - Error in ASGI Framework


Traceback (most recent call last):
  File "/home/kolo/Python_Projects/Product_Analyzer/venv/lib/python3.11/site-packages/hypercorn/asyncio/task_group.py", line 27, in _handle
    await app(scope, receive, send, sync_spawn, call_soon)
  File "/home/kolo/Python_Projects/Product_Analyzer/venv/lib/python3.11/site-packages/hypercorn/app_wrappers.py", line 34, in __call__
    await self.app(scope, receive, send)
  File "/home/kolo/Python_Projects/Product_Analyzer/venv/lib/python3.11/site-packages/quart/app.py", line 1667, in __call__
    await self.asgi_app(scope, receive, send)
  File "/home/kolo/Python_Projects/Product_Analyzer/venv/lib/python3.11/site-packages/quart/app.py", line 1693, in asgi_app
    await asgi_handler(receive, send)
  File "/home/kolo/Python_Projects/Product_Analyzer/venv/lib/python3.11/site-packages/quart/asgi.py", line 52, in __call__
    raise_task_exceptions(done)
  File "/home/kolo/Python_Projects/Product_Analyzer/venv/lib/python3.11/site-packages/quart/utils.py", line 180, in raise_task_exceptions
    raise task.exception()
  File "/home/kolo/Python_Projects/Product_Analyzer/venv/lib/python3.11/site-packages/quart/asgi.py", line 100, in handle_request
    response = await _handle_exception(self.app, error)
               ^^^^^^^^^^^^^^^^^^^^^^^^^^^^^^^^^^^^^^^^
  File "/home/kolo/Python_Projects/Product_Analyzer/venv/lib/python3.11/site-packages/quart/asgi.py", line 357, in _handle_exception
    raise error
  File "/home/kolo/Python_Projects/Product_Analyzer/venv/lib/python3.11/site-packages/quart/asgi.py", line 98, in handle_request
    response = await self.app.handle_request(request)
               ^^^^^^^^^^^^^^^^^^^^^^^^^^^^^^^^^^^^^^
  File "/home/kolo/Python_Projects/Product_Analyzer/venv/lib/python3.11/site-packages/quart/app.py", line 1407, in handle_request
    return await self.handle_exception(error)
           ^^^^^^^^^^^^^^^^^^^^^^^^^^^^^^^^^^
  File "/home/kolo/Python_Projects/Product_Analyzer/venv/lib/python3.11/site-packages/quart/app.py", line 1403, in handle_request
    return await self.full_dispatch_request(request_context)
           ^^^^^^^^^^^^^^^^^^^^^^^^^^^^^^^^^^^^^^^^^^^^^^^^^
  File "/home/kolo/Python_Projects/Product_Analyzer/venv/lib/python3.11/site-packages/quart/app.py", line 1441, in full_dispatch_request
    result = await self.handle_user_exception(error)
             ^^^^^^^^^^^^^^^^^^^^^^^^^^^^^^^^^^^^^^^
  File "/home/kolo/Python_Projects/Product_Analyzer/venv/lib/python3.11/site-packages/quart/app.py", line 1029, in handle_user_exception
    raise error
  File "/home/kolo/Python_Projects/Product_Analyzer/venv/lib/python3.11/site-packages/quart/app.py", line 1439, in full_dispatch_request
    result = await self.dispatch_request(request_context)
             ^^^^^^^^^^^^^^^^^^^^^^^^^^^^^^^^^^^^^^^^^^^^
  File "/home/kolo/Python_Projects/Product_Analyzer/venv/lib/python3.11/site-packages/quart/app.py", line 1535, in dispatch_request
    return await self.ensure_async(handler)(**request_.view_args)  # type: ignore
                 ^^^^^^^^^^^^^^^^^^^^^^^^^^^^^^^^^^^^^^^^^^^^^^^^
TypeError: main_view() missing 1 required positional argument: 'username'
2024-10-11 20:07:10,957 - root - WARNING - Start Product Analyzer...



2024-10-11 20:07:10,966 - hypercorn.error - INFO - Running on http://127.0.0.1:5000 (CTRL + C to quit)



2024-10-11 20:07:59,579 - asyncio - WARNING - Executing <Task pending name='Task-24' coro=<ASGIHTTPConnection.handle_request() running at /home/kolo/Python_Projects/Product_Analyzer/venv/lib/python3.11/site-packages/quart/asgi.py:107> wait_for=<Future pending cb=[Task.task_wakeup()] created at /usr/lib/python3.11/asyncio/base_events.py:427> cb=[_wait.<locals>._on_completion() at /usr/lib/python3.11/asyncio/tasks.py:509] created at /usr/lib/python3.11/asyncio/tasks.py:670> took 17.862 seconds



2024-10-11 20:08:47,372 - root - WARNING - Start Product Analyzer...



2024-10-11 20:08:47,381 - hypercorn.error - INFO - Running on http://127.0.0.1:5000 (CTRL + C to quit)



2024-10-11 20:09:24,618 - root - WARNING - Start Product Analyzer...



2024-10-11 20:09:24,627 - hypercorn.error - INFO - Running on http://127.0.0.1:5000 (CTRL + C to quit)



2024-10-11 20:09:45,270 - asyncio - WARNING - Executing <Task pending name='Task-13' coro=<ASGIHTTPConnection.handle_request() running at /home/kolo/Python_Projects/Product_Analyzer/venv/lib/python3.11/site-packages/quart/asgi.py:107> wait_for=<Future pending cb=[Task.task_wakeup()] created at /usr/lib/python3.11/asyncio/base_events.py:427> cb=[_wait.<locals>._on_completion() at /usr/lib/python3.11/asyncio/tasks.py:509] created at /usr/lib/python3.11/asyncio/tasks.py:670> took 5.567 seconds



2024-10-11 20:12:07,024 - root - WARNING - Start Product Analyzer...



2024-10-11 20:12:07,033 - hypercorn.error - INFO - Running on http://127.0.0.1:5000 (CTRL + C to quit)



2024-10-11 20:12:14,736 - hypercorn.error - ERROR - Error in ASGI Framework


Traceback (most recent call last):
  File "/home/kolo/Python_Projects/Product_Analyzer/venv/lib/python3.11/site-packages/hypercorn/asyncio/task_group.py", line 27, in _handle
    await app(scope, receive, send, sync_spawn, call_soon)
  File "/home/kolo/Python_Projects/Product_Analyzer/venv/lib/python3.11/site-packages/hypercorn/app_wrappers.py", line 34, in __call__
    await self.app(scope, receive, send)
  File "/home/kolo/Python_Projects/Product_Analyzer/venv/lib/python3.11/site-packages/quart/app.py", line 1667, in __call__
    await self.asgi_app(scope, receive, send)
  File "/home/kolo/Python_Projects/Product_Analyzer/venv/lib/python3.11/site-packages/quart/app.py", line 1693, in asgi_app
    await asgi_handler(receive, send)
  File "/home/kolo/Python_Projects/Product_Analyzer/venv/lib/python3.11/site-packages/quart/asgi.py", line 52, in __call__
    raise_task_exceptions(done)
  File "/home/kolo/Python_Projects/Product_Analyzer/venv/lib/python3.11/site-packages/quart/utils.py", line 180, in raise_task_exceptions
    raise task.exception()
  File "/home/kolo/Python_Projects/Product_Analyzer/venv/lib/python3.11/site-packages/quart/asgi.py", line 100, in handle_request
    response = await _handle_exception(self.app, error)
               ^^^^^^^^^^^^^^^^^^^^^^^^^^^^^^^^^^^^^^^^
  File "/home/kolo/Python_Projects/Product_Analyzer/venv/lib/python3.11/site-packages/quart/asgi.py", line 357, in _handle_exception
    raise error
  File "/home/kolo/Python_Projects/Product_Analyzer/venv/lib/python3.11/site-packages/quart/asgi.py", line 98, in handle_request
    response = await self.app.handle_request(request)
               ^^^^^^^^^^^^^^^^^^^^^^^^^^^^^^^^^^^^^^
  File "/home/kolo/Python_Projects/Product_Analyzer/venv/lib/python3.11/site-packages/quart/app.py", line 1407, in handle_request
    return await self.handle_exception(error)
           ^^^^^^^^^^^^^^^^^^^^^^^^^^^^^^^^^^
  File "/home/kolo/Python_Projects/Product_Analyzer/venv/lib/python3.11/site-packages/quart/app.py", line 1403, in handle_request
    return await self.full_dispatch_request(request_context)
           ^^^^^^^^^^^^^^^^^^^^^^^^^^^^^^^^^^^^^^^^^^^^^^^^^
  File "/home/kolo/Python_Projects/Product_Analyzer/venv/lib/python3.11/site-packages/quart/app.py", line 1441, in full_dispatch_request
    result = await self.handle_user_exception(error)
             ^^^^^^^^^^^^^^^^^^^^^^^^^^^^^^^^^^^^^^^
  File "/home/kolo/Python_Projects/Product_Analyzer/venv/lib/python3.11/site-packages/quart/app.py", line 1029, in handle_user_exception
    raise error
  File "/home/kolo/Python_Projects/Product_Analyzer/venv/lib/python3.11/site-packages/quart/app.py", line 1439, in full_dispatch_request
    result = await self.dispatch_request(request_context)
             ^^^^^^^^^^^^^^^^^^^^^^^^^^^^^^^^^^^^^^^^^^^^
  File "/home/kolo/Python_Projects/Product_Analyzer/venv/lib/python3.11/site-packages/quart/app.py", line 1535, in dispatch_request
    return await self.ensure_async(handler)(**request_.view_args)  # type: ignore
           ^^^^^^^^^^^^^^^^^^^^^^^^^^^^^^^^^^^^^^^^^^^^^^^^^^^^^^
  File "/home/kolo/Python_Projects/Product_Analyzer/venv/lib/python3.11/site-packages/quart/utils.py", line 57, in _wrapper
    result = await loop.run_in_executor(
             ^^^^^^^^^^^^^^^^^^^^^^^^^^^
  File "/usr/lib/python3.11/concurrent/futures/thread.py", line 58, in run
    result = self.fn(*self.args, **self.kwargs)
             ^^^^^^^^^^^^^^^^^^^^^^^^^^^^^^^^^^
  File "/home/kolo/Python_Projects/Product_Analyzer/venv/lib/python3.11/site-packages/flask_httpauth.py", line 150, in decorated
    auth = self.get_auth()
           ^^^^^^^^^^^^^^^
  File "/home/kolo/Python_Projects/Product_Analyzer/venv/lib/python3.11/site-packages/flask_httpauth.py", line 217, in get_auth
    if header not in request.headers:
                     ^^^^^^^^^^^^^^^
  File "/home/kolo/Python_Projects/Product_Analyzer/venv/lib/python3.11/site-packages/werkzeug/local.py", line 318, in __get__
    obj = instance._get_current_object()
          ^^^^^^^^^^^^^^^^^^^^^^^^^^^^^^
  File "/home/kolo/Python_Projects/Product_Analyzer/venv/lib/python3.11/site-packages/werkzeug/local.py", line 519, in _get_current_object
    raise RuntimeError(unbound_message) from None
RuntimeError: Working outside of request context.

This typically means that you attempted to use functionality that needed
an active HTTP request. Consult the documentation on testing for
information about how to avoid this problem.
2024-10-11 20:12:49,012 - root - WARNING - Start Product Analyzer...



2024-10-11 20:12:49,022 - hypercorn.error - INFO - Running on http://127.0.0.1:5000 (CTRL + C to quit)



2024-10-11 20:12:58,910 - hypercorn.error - ERROR - Error in ASGI Framework


Traceback (most recent call last):
  File "/home/kolo/Python_Projects/Product_Analyzer/venv/lib/python3.11/site-packages/hypercorn/asyncio/task_group.py", line 27, in _handle
    await app(scope, receive, send, sync_spawn, call_soon)
  File "/home/kolo/Python_Projects/Product_Analyzer/venv/lib/python3.11/site-packages/hypercorn/app_wrappers.py", line 34, in __call__
    await self.app(scope, receive, send)
  File "/home/kolo/Python_Projects/Product_Analyzer/venv/lib/python3.11/site-packages/quart/app.py", line 1667, in __call__
    await self.asgi_app(scope, receive, send)
  File "/home/kolo/Python_Projects/Product_Analyzer/venv/lib/python3.11/site-packages/quart/app.py", line 1693, in asgi_app
    await asgi_handler(receive, send)
  File "/home/kolo/Python_Projects/Product_Analyzer/venv/lib/python3.11/site-packages/quart/asgi.py", line 52, in __call__
    raise_task_exceptions(done)
  File "/home/kolo/Python_Projects/Product_Analyzer/venv/lib/python3.11/site-packages/quart/utils.py", line 180, in raise_task_exceptions
    raise task.exception()
  File "/home/kolo/Python_Projects/Product_Analyzer/venv/lib/python3.11/site-packages/quart/asgi.py", line 100, in handle_request
    response = await _handle_exception(self.app, error)
               ^^^^^^^^^^^^^^^^^^^^^^^^^^^^^^^^^^^^^^^^
  File "/home/kolo/Python_Projects/Product_Analyzer/venv/lib/python3.11/site-packages/quart/asgi.py", line 357, in _handle_exception
    raise error
  File "/home/kolo/Python_Projects/Product_Analyzer/venv/lib/python3.11/site-packages/quart/asgi.py", line 98, in handle_request
    response = await self.app.handle_request(request)
               ^^^^^^^^^^^^^^^^^^^^^^^^^^^^^^^^^^^^^^
  File "/home/kolo/Python_Projects/Product_Analyzer/venv/lib/python3.11/site-packages/quart/app.py", line 1407, in handle_request
    return await self.handle_exception(error)
           ^^^^^^^^^^^^^^^^^^^^^^^^^^^^^^^^^^
  File "/home/kolo/Python_Projects/Product_Analyzer/venv/lib/python3.11/site-packages/quart/app.py", line 1403, in handle_request
    return await self.full_dispatch_request(request_context)
           ^^^^^^^^^^^^^^^^^^^^^^^^^^^^^^^^^^^^^^^^^^^^^^^^^
  File "/home/kolo/Python_Projects/Product_Analyzer/venv/lib/python3.11/site-packages/quart/app.py", line 1441, in full_dispatch_request
    result = await self.handle_user_exception(error)
             ^^^^^^^^^^^^^^^^^^^^^^^^^^^^^^^^^^^^^^^
  File "/home/kolo/Python_Projects/Product_Analyzer/venv/lib/python3.11/site-packages/quart/app.py", line 1029, in handle_user_exception
    raise error
  File "/home/kolo/Python_Projects/Product_Analyzer/venv/lib/python3.11/site-packages/quart/app.py", line 1439, in full_dispatch_request
    result = await self.dispatch_request(request_context)
             ^^^^^^^^^^^^^^^^^^^^^^^^^^^^^^^^^^^^^^^^^^^^
  File "/home/kolo/Python_Projects/Product_Analyzer/venv/lib/python3.11/site-packages/quart/app.py", line 1535, in dispatch_request
    return await self.ensure_async(handler)(**request_.view_args)  # type: ignore
           ^^^^^^^^^^^^^^^^^^^^^^^^^^^^^^^^^^^^^^^^^^^^^^^^^^^^^^
  File "/home/kolo/Python_Projects/Product_Analyzer/venv/lib/python3.11/site-packages/quart/utils.py", line 57, in _wrapper
    result = await loop.run_in_executor(
             ^^^^^^^^^^^^^^^^^^^^^^^^^^^
  File "/usr/lib/python3.11/concurrent/futures/thread.py", line 58, in run
    result = self.fn(*self.args, **self.kwargs)
             ^^^^^^^^^^^^^^^^^^^^^^^^^^^^^^^^^^
  File "/home/kolo/Python_Projects/Product_Analyzer/venv/lib/python3.11/site-packages/flask_httpauth.py", line 150, in decorated
    auth = self.get_auth()
           ^^^^^^^^^^^^^^^
  File "/home/kolo/Python_Projects/Product_Analyzer/venv/lib/python3.11/site-packages/flask_httpauth.py", line 217, in get_auth
    if header not in request.headers:
                     ^^^^^^^^^^^^^^^
  File "/home/kolo/Python_Projects/Product_Analyzer/venv/lib/python3.11/site-packages/werkzeug/local.py", line 318, in __get__
    obj = instance._get_current_object()
          ^^^^^^^^^^^^^^^^^^^^^^^^^^^^^^
  File "/home/kolo/Python_Projects/Product_Analyzer/venv/lib/python3.11/site-packages/werkzeug/local.py", line 519, in _get_current_object
    raise RuntimeError(unbound_message) from None
RuntimeError: Working outside of request context.

This typically means that you attempted to use functionality that needed
an active HTTP request. Consult the documentation on testing for
information about how to avoid this problem.
2024-10-11 20:17:35,487 - root - WARNING - Start Product Analyzer...



2024-10-11 20:17:35,498 - hypercorn.error - INFO - Running on http://127.0.0.1:5000 (CTRL + C to quit)



2024-10-11 20:17:56,539 - hypercorn.error - ERROR - Error in ASGI Framework


Traceback (most recent call last):
  File "/home/kolo/Python_Projects/Product_Analyzer/venv/lib/python3.11/site-packages/hypercorn/asyncio/task_group.py", line 27, in _handle
    await app(scope, receive, send, sync_spawn, call_soon)
  File "/home/kolo/Python_Projects/Product_Analyzer/venv/lib/python3.11/site-packages/hypercorn/app_wrappers.py", line 34, in __call__
    await self.app(scope, receive, send)
  File "/home/kolo/Python_Projects/Product_Analyzer/venv/lib/python3.11/site-packages/quart/app.py", line 1667, in __call__
    await self.asgi_app(scope, receive, send)
  File "/home/kolo/Python_Projects/Product_Analyzer/venv/lib/python3.11/site-packages/quart/app.py", line 1693, in asgi_app
    await asgi_handler(receive, send)
  File "/home/kolo/Python_Projects/Product_Analyzer/venv/lib/python3.11/site-packages/quart/asgi.py", line 52, in __call__
    raise_task_exceptions(done)
  File "/home/kolo/Python_Projects/Product_Analyzer/venv/lib/python3.11/site-packages/quart/utils.py", line 180, in raise_task_exceptions
    raise task.exception()
  File "/home/kolo/Python_Projects/Product_Analyzer/venv/lib/python3.11/site-packages/quart/asgi.py", line 100, in handle_request
    response = await _handle_exception(self.app, error)
               ^^^^^^^^^^^^^^^^^^^^^^^^^^^^^^^^^^^^^^^^
  File "/home/kolo/Python_Projects/Product_Analyzer/venv/lib/python3.11/site-packages/quart/asgi.py", line 357, in _handle_exception
    raise error
  File "/home/kolo/Python_Projects/Product_Analyzer/venv/lib/python3.11/site-packages/quart/asgi.py", line 98, in handle_request
    response = await self.app.handle_request(request)
               ^^^^^^^^^^^^^^^^^^^^^^^^^^^^^^^^^^^^^^
  File "/home/kolo/Python_Projects/Product_Analyzer/venv/lib/python3.11/site-packages/quart/app.py", line 1407, in handle_request
    return await self.handle_exception(error)
           ^^^^^^^^^^^^^^^^^^^^^^^^^^^^^^^^^^
  File "/home/kolo/Python_Projects/Product_Analyzer/venv/lib/python3.11/site-packages/quart/app.py", line 1403, in handle_request
    return await self.full_dispatch_request(request_context)
           ^^^^^^^^^^^^^^^^^^^^^^^^^^^^^^^^^^^^^^^^^^^^^^^^^
  File "/home/kolo/Python_Projects/Product_Analyzer/venv/lib/python3.11/site-packages/quart/app.py", line 1441, in full_dispatch_request
    result = await self.handle_user_exception(error)
             ^^^^^^^^^^^^^^^^^^^^^^^^^^^^^^^^^^^^^^^
  File "/home/kolo/Python_Projects/Product_Analyzer/venv/lib/python3.11/site-packages/quart/app.py", line 1029, in handle_user_exception
    raise error
  File "/home/kolo/Python_Projects/Product_Analyzer/venv/lib/python3.11/site-packages/quart/app.py", line 1439, in full_dispatch_request
    result = await self.dispatch_request(request_context)
             ^^^^^^^^^^^^^^^^^^^^^^^^^^^^^^^^^^^^^^^^^^^^
  File "/home/kolo/Python_Projects/Product_Analyzer/venv/lib/python3.11/site-packages/quart/app.py", line 1535, in dispatch_request
    return await self.ensure_async(handler)(**request_.view_args)  # type: ignore
           ^^^^^^^^^^^^^^^^^^^^^^^^^^^^^^^^^^^^^^^^^^^^^^^^^^^^^^
  File "/home/kolo/Python_Projects/Product_Analyzer/venv/lib/python3.11/site-packages/quart/utils.py", line 57, in _wrapper
    result = await loop.run_in_executor(
             ^^^^^^^^^^^^^^^^^^^^^^^^^^^
  File "/usr/lib/python3.11/concurrent/futures/thread.py", line 58, in run
    result = self.fn(*self.args, **self.kwargs)
             ^^^^^^^^^^^^^^^^^^^^^^^^^^^^^^^^^^
  File "/home/kolo/Python_Projects/Product_Analyzer/venv/lib/python3.11/site-packages/flask_httpauth.py", line 150, in decorated
    auth = self.get_auth()
           ^^^^^^^^^^^^^^^
  File "/home/kolo/Python_Projects/Product_Analyzer/venv/lib/python3.11/site-packages/flask_httpauth.py", line 217, in get_auth
    if header not in request.headers:
                     ^^^^^^^^^^^^^^^
  File "/home/kolo/Python_Projects/Product_Analyzer/venv/lib/python3.11/site-packages/werkzeug/local.py", line 318, in __get__
    obj = instance._get_current_object()
          ^^^^^^^^^^^^^^^^^^^^^^^^^^^^^^
  File "/home/kolo/Python_Projects/Product_Analyzer/venv/lib/python3.11/site-packages/werkzeug/local.py", line 519, in _get_current_object
    raise RuntimeError(unbound_message) from None
RuntimeError: Working outside of request context.

This typically means that you attempted to use functionality that needed
an active HTTP request. Consult the documentation on testing for
information about how to avoid this problem.
2024-10-11 20:18:16,214 - root - WARNING - Start Product Analyzer...



2024-10-11 20:18:16,230 - hypercorn.error - INFO - Running on http://127.0.0.1:5000 (CTRL + C to quit)



2024-10-11 20:20:44,316 - root - WARNING - Start Product Analyzer...



2024-10-11 20:20:44,325 - hypercorn.error - INFO - Running on http://127.0.0.1:5000 (CTRL + C to quit)



2024-10-11 20:20:52,610 - hypercorn.error - ERROR - Error in ASGI Framework


Traceback (most recent call last):
  File "/home/kolo/Python_Projects/Product_Analyzer/venv/lib/python3.11/site-packages/quart_httpauth.py", line 178, in decorated
    return await self.auth_error_callback(status)
           ^^^^^^^^^^^^^^^^^^^^^^^^^^^^^^^^^^^^^^
  File "/home/kolo/Python_Projects/Product_Analyzer/venv/lib/python3.11/site-packages/quart_httpauth.py", line 62, in decorated
    res = await self.ensure_async(f)(*args, **kwargs)
          ^^^^^^^^^^^^^^^^^^^^^^^^^^^^^^^^^^^^^^^^^^^
  File "/home/kolo/Python_Projects/Product_Analyzer/venv/lib/python3.11/site-packages/quart/utils.py", line 57, in _wrapper
    result = await loop.run_in_executor(
             ^^^^^^^^^^^^^^^^^^^^^^^^^^^
  File "/usr/lib/python3.11/concurrent/futures/thread.py", line 58, in run
    result = self.fn(*self.args, **self.kwargs)
             ^^^^^^^^^^^^^^^^^^^^^^^^^^^^^^^^^^
TypeError: unauthorized() takes 0 positional arguments but 1 was given

During handling of the above exception, another exception occurred:

Traceback (most recent call last):
  File "/home/kolo/Python_Projects/Product_Analyzer/venv/lib/python3.11/site-packages/hypercorn/asyncio/task_group.py", line 27, in _handle
    await app(scope, receive, send, sync_spawn, call_soon)
  File "/home/kolo/Python_Projects/Product_Analyzer/venv/lib/python3.11/site-packages/hypercorn/app_wrappers.py", line 34, in __call__
    await self.app(scope, receive, send)
  File "/home/kolo/Python_Projects/Product_Analyzer/venv/lib/python3.11/site-packages/quart/app.py", line 1667, in __call__
    await self.asgi_app(scope, receive, send)
  File "/home/kolo/Python_Projects/Product_Analyzer/venv/lib/python3.11/site-packages/quart/app.py", line 1693, in asgi_app
    await asgi_handler(receive, send)
  File "/home/kolo/Python_Projects/Product_Analyzer/venv/lib/python3.11/site-packages/quart/asgi.py", line 52, in __call__
    raise_task_exceptions(done)
  File "/home/kolo/Python_Projects/Product_Analyzer/venv/lib/python3.11/site-packages/quart/utils.py", line 180, in raise_task_exceptions
    raise task.exception()
  File "/home/kolo/Python_Projects/Product_Analyzer/venv/lib/python3.11/site-packages/quart/asgi.py", line 100, in handle_request
    response = await _handle_exception(self.app, error)
               ^^^^^^^^^^^^^^^^^^^^^^^^^^^^^^^^^^^^^^^^
  File "/home/kolo/Python_Projects/Product_Analyzer/venv/lib/python3.11/site-packages/quart/asgi.py", line 357, in _handle_exception
    raise error
  File "/home/kolo/Python_Projects/Product_Analyzer/venv/lib/python3.11/site-packages/quart/asgi.py", line 98, in handle_request
    response = await self.app.handle_request(request)
               ^^^^^^^^^^^^^^^^^^^^^^^^^^^^^^^^^^^^^^
  File "/home/kolo/Python_Projects/Product_Analyzer/venv/lib/python3.11/site-packages/quart/app.py", line 1407, in handle_request
    return await self.handle_exception(error)
           ^^^^^^^^^^^^^^^^^^^^^^^^^^^^^^^^^^
  File "/home/kolo/Python_Projects/Product_Analyzer/venv/lib/python3.11/site-packages/quart/app.py", line 1403, in handle_request
    return await self.full_dispatch_request(request_context)
           ^^^^^^^^^^^^^^^^^^^^^^^^^^^^^^^^^^^^^^^^^^^^^^^^^
  File "/home/kolo/Python_Projects/Product_Analyzer/venv/lib/python3.11/site-packages/quart/app.py", line 1441, in full_dispatch_request
    result = await self.handle_user_exception(error)
             ^^^^^^^^^^^^^^^^^^^^^^^^^^^^^^^^^^^^^^^
  File "/home/kolo/Python_Projects/Product_Analyzer/venv/lib/python3.11/site-packages/quart/app.py", line 1029, in handle_user_exception
    raise error
  File "/home/kolo/Python_Projects/Product_Analyzer/venv/lib/python3.11/site-packages/quart/app.py", line 1439, in full_dispatch_request
    result = await self.dispatch_request(request_context)
             ^^^^^^^^^^^^^^^^^^^^^^^^^^^^^^^^^^^^^^^^^^^^
  File "/home/kolo/Python_Projects/Product_Analyzer/venv/lib/python3.11/site-packages/quart/app.py", line 1535, in dispatch_request
    return await self.ensure_async(handler)(**request_.view_args)  # type: ignore
           ^^^^^^^^^^^^^^^^^^^^^^^^^^^^^^^^^^^^^^^^^^^^^^^^^^^^^^
  File "/home/kolo/Python_Projects/Product_Analyzer/venv/lib/python3.11/site-packages/quart_httpauth.py", line 180, in decorated
    return await self.auth_error_callback()
           ^^^^^^^^^^^^^^^^^^^^^^^^^^^^^^^^
  File "/home/kolo/Python_Projects/Product_Analyzer/venv/lib/python3.11/site-packages/quart_httpauth.py", line 64, in decorated
    res = await make_response(res)
          ^^^^^^^^^^^^^^^^^^^^^^^^
  File "/home/kolo/Python_Projects/Product_Analyzer/venv/lib/python3.11/site-packages/quart/helpers.py", line 71, in make_response
    return await current_app.make_response(cast(ResponseReturnValue, args))
           ^^^^^^^^^^^^^^^^^^^^^^^^^^^^^^^^^^^^^^^^^^^^^^^^^^^^^^^^^^^^^^^^
  File "/home/kolo/Python_Projects/Product_Analyzer/venv/lib/python3.11/site-packages/quart/app.py", line 1388, in make_response
    raise TypeError(f"The response value type ({type(value).__name__}) is not valid")
TypeError: The response value type (coroutine) is not valid
2024-10-11 20:21:26,757 - root - WARNING - Start Product Analyzer...



2024-10-11 20:21:26,766 - hypercorn.error - INFO - Running on http://127.0.0.1:5000 (CTRL + C to quit)



2024-10-11 20:21:28,699 - hypercorn.error - ERROR - Error in ASGI Framework


Traceback (most recent call last):
  File "/home/kolo/Python_Projects/Product_Analyzer/venv/lib/python3.11/site-packages/quart_httpauth.py", line 178, in decorated
    return await self.auth_error_callback(status)
           ^^^^^^^^^^^^^^^^^^^^^^^^^^^^^^^^^^^^^^
  File "/home/kolo/Python_Projects/Product_Analyzer/venv/lib/python3.11/site-packages/quart_httpauth.py", line 62, in decorated
    res = await self.ensure_async(f)(*args, **kwargs)
          ^^^^^^^^^^^^^^^^^^^^^^^^^^^^^^^^^^^^^^^^^^^
  File "/home/kolo/Python_Projects/Product_Analyzer/venv/lib/python3.11/site-packages/quart/utils.py", line 57, in _wrapper
    result = await loop.run_in_executor(
             ^^^^^^^^^^^^^^^^^^^^^^^^^^^
  File "/usr/lib/python3.11/concurrent/futures/thread.py", line 58, in run
    result = self.fn(*self.args, **self.kwargs)
             ^^^^^^^^^^^^^^^^^^^^^^^^^^^^^^^^^^
TypeError: unauthorized() takes 0 positional arguments but 1 was given

During handling of the above exception, another exception occurred:

Traceback (most recent call last):
  File "/home/kolo/Python_Projects/Product_Analyzer/venv/lib/python3.11/site-packages/hypercorn/asyncio/task_group.py", line 27, in _handle
    await app(scope, receive, send, sync_spawn, call_soon)
  File "/home/kolo/Python_Projects/Product_Analyzer/venv/lib/python3.11/site-packages/hypercorn/app_wrappers.py", line 34, in __call__
    await self.app(scope, receive, send)
  File "/home/kolo/Python_Projects/Product_Analyzer/venv/lib/python3.11/site-packages/quart/app.py", line 1667, in __call__
    await self.asgi_app(scope, receive, send)
  File "/home/kolo/Python_Projects/Product_Analyzer/venv/lib/python3.11/site-packages/quart/app.py", line 1693, in asgi_app
    await asgi_handler(receive, send)
  File "/home/kolo/Python_Projects/Product_Analyzer/venv/lib/python3.11/site-packages/quart/asgi.py", line 52, in __call__
    raise_task_exceptions(done)
  File "/home/kolo/Python_Projects/Product_Analyzer/venv/lib/python3.11/site-packages/quart/utils.py", line 180, in raise_task_exceptions
    raise task.exception()
  File "/home/kolo/Python_Projects/Product_Analyzer/venv/lib/python3.11/site-packages/quart/asgi.py", line 100, in handle_request
    response = await _handle_exception(self.app, error)
               ^^^^^^^^^^^^^^^^^^^^^^^^^^^^^^^^^^^^^^^^
  File "/home/kolo/Python_Projects/Product_Analyzer/venv/lib/python3.11/site-packages/quart/asgi.py", line 357, in _handle_exception
    raise error
  File "/home/kolo/Python_Projects/Product_Analyzer/venv/lib/python3.11/site-packages/quart/asgi.py", line 98, in handle_request
    response = await self.app.handle_request(request)
               ^^^^^^^^^^^^^^^^^^^^^^^^^^^^^^^^^^^^^^
  File "/home/kolo/Python_Projects/Product_Analyzer/venv/lib/python3.11/site-packages/quart/app.py", line 1407, in handle_request
    return await self.handle_exception(error)
           ^^^^^^^^^^^^^^^^^^^^^^^^^^^^^^^^^^
  File "/home/kolo/Python_Projects/Product_Analyzer/venv/lib/python3.11/site-packages/quart/app.py", line 1403, in handle_request
    return await self.full_dispatch_request(request_context)
           ^^^^^^^^^^^^^^^^^^^^^^^^^^^^^^^^^^^^^^^^^^^^^^^^^
  File "/home/kolo/Python_Projects/Product_Analyzer/venv/lib/python3.11/site-packages/quart/app.py", line 1441, in full_dispatch_request
    result = await self.handle_user_exception(error)
             ^^^^^^^^^^^^^^^^^^^^^^^^^^^^^^^^^^^^^^^
  File "/home/kolo/Python_Projects/Product_Analyzer/venv/lib/python3.11/site-packages/quart/app.py", line 1029, in handle_user_exception
    raise error
  File "/home/kolo/Python_Projects/Product_Analyzer/venv/lib/python3.11/site-packages/quart/app.py", line 1439, in full_dispatch_request
    result = await self.dispatch_request(request_context)
             ^^^^^^^^^^^^^^^^^^^^^^^^^^^^^^^^^^^^^^^^^^^^
  File "/home/kolo/Python_Projects/Product_Analyzer/venv/lib/python3.11/site-packages/quart/app.py", line 1535, in dispatch_request
    return await self.ensure_async(handler)(**request_.view_args)  # type: ignore
           ^^^^^^^^^^^^^^^^^^^^^^^^^^^^^^^^^^^^^^^^^^^^^^^^^^^^^^
  File "/home/kolo/Python_Projects/Product_Analyzer/venv/lib/python3.11/site-packages/quart_httpauth.py", line 180, in decorated
    return await self.auth_error_callback()
           ^^^^^^^^^^^^^^^^^^^^^^^^^^^^^^^^
  File "/home/kolo/Python_Projects/Product_Analyzer/venv/lib/python3.11/site-packages/quart_httpauth.py", line 64, in decorated
    res = await make_response(res)
          ^^^^^^^^^^^^^^^^^^^^^^^^
  File "/home/kolo/Python_Projects/Product_Analyzer/venv/lib/python3.11/site-packages/quart/helpers.py", line 71, in make_response
    return await current_app.make_response(cast(ResponseReturnValue, args))
           ^^^^^^^^^^^^^^^^^^^^^^^^^^^^^^^^^^^^^^^^^^^^^^^^^^^^^^^^^^^^^^^^
  File "/home/kolo/Python_Projects/Product_Analyzer/venv/lib/python3.11/site-packages/quart/app.py", line 1388, in make_response
    raise TypeError(f"The response value type ({type(value).__name__}) is not valid")
TypeError: The response value type (coroutine) is not valid
2024-10-11 20:22:49,070 - root - WARNING - Start Product Analyzer...



2024-10-11 20:22:49,079 - hypercorn.error - INFO - Running on http://127.0.0.1:5000 (CTRL + C to quit)



2024-10-11 20:22:52,297 - hypercorn.error - ERROR - Error in ASGI Framework


Traceback (most recent call last):
  File "/home/kolo/Python_Projects/Product_Analyzer/venv/lib/python3.11/site-packages/quart_httpauth.py", line 178, in decorated
    return await self.auth_error_callback(status)
           ^^^^^^^^^^^^^^^^^^^^^^^^^^^^^^^^^^^^^^
  File "/home/kolo/Python_Projects/Product_Analyzer/venv/lib/python3.11/site-packages/quart_httpauth.py", line 62, in decorated
    res = await self.ensure_async(f)(*args, **kwargs)
                ^^^^^^^^^^^^^^^^^^^^^^^^^^^^^^^^^^^^^
TypeError: unauthorized() takes 0 positional arguments but 1 was given

During handling of the above exception, another exception occurred:

Traceback (most recent call last):
  File "/home/kolo/Python_Projects/Product_Analyzer/venv/lib/python3.11/site-packages/hypercorn/asyncio/task_group.py", line 27, in _handle
    await app(scope, receive, send, sync_spawn, call_soon)
  File "/home/kolo/Python_Projects/Product_Analyzer/venv/lib/python3.11/site-packages/hypercorn/app_wrappers.py", line 34, in __call__
    await self.app(scope, receive, send)
  File "/home/kolo/Python_Projects/Product_Analyzer/venv/lib/python3.11/site-packages/quart/app.py", line 1667, in __call__
    await self.asgi_app(scope, receive, send)
  File "/home/kolo/Python_Projects/Product_Analyzer/venv/lib/python3.11/site-packages/quart/app.py", line 1693, in asgi_app
    await asgi_handler(receive, send)
  File "/home/kolo/Python_Projects/Product_Analyzer/venv/lib/python3.11/site-packages/quart/asgi.py", line 52, in __call__
    raise_task_exceptions(done)
  File "/home/kolo/Python_Projects/Product_Analyzer/venv/lib/python3.11/site-packages/quart/utils.py", line 180, in raise_task_exceptions
    raise task.exception()
  File "/home/kolo/Python_Projects/Product_Analyzer/venv/lib/python3.11/site-packages/quart/asgi.py", line 100, in handle_request
    response = await _handle_exception(self.app, error)
               ^^^^^^^^^^^^^^^^^^^^^^^^^^^^^^^^^^^^^^^^
  File "/home/kolo/Python_Projects/Product_Analyzer/venv/lib/python3.11/site-packages/quart/asgi.py", line 357, in _handle_exception
    raise error
  File "/home/kolo/Python_Projects/Product_Analyzer/venv/lib/python3.11/site-packages/quart/asgi.py", line 98, in handle_request
    response = await self.app.handle_request(request)
               ^^^^^^^^^^^^^^^^^^^^^^^^^^^^^^^^^^^^^^
  File "/home/kolo/Python_Projects/Product_Analyzer/venv/lib/python3.11/site-packages/quart/app.py", line 1407, in handle_request
    return await self.handle_exception(error)
           ^^^^^^^^^^^^^^^^^^^^^^^^^^^^^^^^^^
  File "/home/kolo/Python_Projects/Product_Analyzer/venv/lib/python3.11/site-packages/quart/app.py", line 1403, in handle_request
    return await self.full_dispatch_request(request_context)
           ^^^^^^^^^^^^^^^^^^^^^^^^^^^^^^^^^^^^^^^^^^^^^^^^^
  File "/home/kolo/Python_Projects/Product_Analyzer/venv/lib/python3.11/site-packages/quart/app.py", line 1441, in full_dispatch_request
    result = await self.handle_user_exception(error)
             ^^^^^^^^^^^^^^^^^^^^^^^^^^^^^^^^^^^^^^^
  File "/home/kolo/Python_Projects/Product_Analyzer/venv/lib/python3.11/site-packages/quart/app.py", line 1029, in handle_user_exception
    raise error
  File "/home/kolo/Python_Projects/Product_Analyzer/venv/lib/python3.11/site-packages/quart/app.py", line 1439, in full_dispatch_request
    result = await self.dispatch_request(request_context)
             ^^^^^^^^^^^^^^^^^^^^^^^^^^^^^^^^^^^^^^^^^^^^
  File "/home/kolo/Python_Projects/Product_Analyzer/venv/lib/python3.11/site-packages/quart/app.py", line 1535, in dispatch_request
    return await self.ensure_async(handler)(**request_.view_args)  # type: ignore
           ^^^^^^^^^^^^^^^^^^^^^^^^^^^^^^^^^^^^^^^^^^^^^^^^^^^^^^
  File "/home/kolo/Python_Projects/Product_Analyzer/venv/lib/python3.11/site-packages/quart_httpauth.py", line 180, in decorated
    return await self.auth_error_callback()
           ^^^^^^^^^^^^^^^^^^^^^^^^^^^^^^^^
  File "/home/kolo/Python_Projects/Product_Analyzer/venv/lib/python3.11/site-packages/quart_httpauth.py", line 64, in decorated
    res = await make_response(res)
          ^^^^^^^^^^^^^^^^^^^^^^^^
  File "/home/kolo/Python_Projects/Product_Analyzer/venv/lib/python3.11/site-packages/quart/helpers.py", line 71, in make_response
    return await current_app.make_response(cast(ResponseReturnValue, args))
           ^^^^^^^^^^^^^^^^^^^^^^^^^^^^^^^^^^^^^^^^^^^^^^^^^^^^^^^^^^^^^^^^
  File "/home/kolo/Python_Projects/Product_Analyzer/venv/lib/python3.11/site-packages/quart/app.py", line 1388, in make_response
    raise TypeError(f"The response value type ({type(value).__name__}) is not valid")
TypeError: The response value type (coroutine) is not valid
2024-10-11 20:24:44,843 - root - WARNING - Start Product Analyzer...



2024-10-11 20:24:44,852 - hypercorn.error - INFO - Running on http://127.0.0.1:5000 (CTRL + C to quit)



2024-10-11 20:30:32,008 - asyncio - WARNING - Executing <Task pending name='Task-24' coro=<ASGIHTTPConnection.handle_request() running at /home/kolo/Python_Projects/Product_Analyzer/venv/lib/python3.11/site-packages/quart/asgi.py:107> wait_for=<Future pending cb=[Task.task_wakeup()] created at /usr/lib/python3.11/asyncio/base_events.py:427> cb=[_wait.<locals>._on_completion() at /usr/lib/python3.11/asyncio/tasks.py:509] created at /usr/lib/python3.11/asyncio/tasks.py:670> took 6.849 seconds



2024-10-11 20:35:10,835 - root - WARNING - Start Product Analyzer...



2024-10-11 20:35:10,845 - hypercorn.error - INFO - Running on http://127.0.0.1:5000 (CTRL + C to quit)



2024-10-11 20:35:16,353 - hypercorn.error - ERROR - Error in ASGI Framework


Traceback (most recent call last):
  File "/home/kolo/Python_Projects/Product_Analyzer/venv/lib/python3.11/site-packages/quart_httpauth.py", line 178, in decorated
    return await self.auth_error_callback(status)
           ^^^^^^^^^^^^^^^^^^^^^^^^^^^^^^^^^^^^^^
  File "/home/kolo/Python_Projects/Product_Analyzer/venv/lib/python3.11/site-packages/quart_httpauth.py", line 62, in decorated
    res = await self.ensure_async(f)(*args, **kwargs)
          ^^^^^^^^^^^^^^^^^^^^^^^^^^^^^^^^^^^^^^^^^^^
  File "/home/kolo/Python_Projects/Product_Analyzer/venv/lib/python3.11/site-packages/quart/utils.py", line 57, in _wrapper
    result = await loop.run_in_executor(
             ^^^^^^^^^^^^^^^^^^^^^^^^^^^
  File "/usr/lib/python3.11/concurrent/futures/thread.py", line 58, in run
    result = self.fn(*self.args, **self.kwargs)
             ^^^^^^^^^^^^^^^^^^^^^^^^^^^^^^^^^^
TypeError: unauthorized() takes 0 positional arguments but 1 was given

During handling of the above exception, another exception occurred:

Traceback (most recent call last):
  File "/home/kolo/Python_Projects/Product_Analyzer/venv/lib/python3.11/site-packages/hypercorn/asyncio/task_group.py", line 27, in _handle
    await app(scope, receive, send, sync_spawn, call_soon)
  File "/home/kolo/Python_Projects/Product_Analyzer/venv/lib/python3.11/site-packages/hypercorn/app_wrappers.py", line 34, in __call__
    await self.app(scope, receive, send)
  File "/home/kolo/Python_Projects/Product_Analyzer/venv/lib/python3.11/site-packages/quart/app.py", line 1667, in __call__
    await self.asgi_app(scope, receive, send)
  File "/home/kolo/Python_Projects/Product_Analyzer/venv/lib/python3.11/site-packages/quart/app.py", line 1693, in asgi_app
    await asgi_handler(receive, send)
  File "/home/kolo/Python_Projects/Product_Analyzer/venv/lib/python3.11/site-packages/quart/asgi.py", line 52, in __call__
    raise_task_exceptions(done)
  File "/home/kolo/Python_Projects/Product_Analyzer/venv/lib/python3.11/site-packages/quart/utils.py", line 180, in raise_task_exceptions
    raise task.exception()
  File "/home/kolo/Python_Projects/Product_Analyzer/venv/lib/python3.11/site-packages/quart/asgi.py", line 100, in handle_request
    response = await _handle_exception(self.app, error)
               ^^^^^^^^^^^^^^^^^^^^^^^^^^^^^^^^^^^^^^^^
  File "/home/kolo/Python_Projects/Product_Analyzer/venv/lib/python3.11/site-packages/quart/asgi.py", line 357, in _handle_exception
    raise error
  File "/home/kolo/Python_Projects/Product_Analyzer/venv/lib/python3.11/site-packages/quart/asgi.py", line 98, in handle_request
    response = await self.app.handle_request(request)
               ^^^^^^^^^^^^^^^^^^^^^^^^^^^^^^^^^^^^^^
  File "/home/kolo/Python_Projects/Product_Analyzer/venv/lib/python3.11/site-packages/quart/app.py", line 1407, in handle_request
    return await self.handle_exception(error)
           ^^^^^^^^^^^^^^^^^^^^^^^^^^^^^^^^^^
  File "/home/kolo/Python_Projects/Product_Analyzer/venv/lib/python3.11/site-packages/quart/app.py", line 1403, in handle_request
    return await self.full_dispatch_request(request_context)
           ^^^^^^^^^^^^^^^^^^^^^^^^^^^^^^^^^^^^^^^^^^^^^^^^^
  File "/home/kolo/Python_Projects/Product_Analyzer/venv/lib/python3.11/site-packages/quart/app.py", line 1441, in full_dispatch_request
    result = await self.handle_user_exception(error)
             ^^^^^^^^^^^^^^^^^^^^^^^^^^^^^^^^^^^^^^^
  File "/home/kolo/Python_Projects/Product_Analyzer/venv/lib/python3.11/site-packages/quart/app.py", line 1029, in handle_user_exception
    raise error
  File "/home/kolo/Python_Projects/Product_Analyzer/venv/lib/python3.11/site-packages/quart/app.py", line 1439, in full_dispatch_request
    result = await self.dispatch_request(request_context)
             ^^^^^^^^^^^^^^^^^^^^^^^^^^^^^^^^^^^^^^^^^^^^
  File "/home/kolo/Python_Projects/Product_Analyzer/venv/lib/python3.11/site-packages/quart/app.py", line 1535, in dispatch_request
    return await self.ensure_async(handler)(**request_.view_args)  # type: ignore
           ^^^^^^^^^^^^^^^^^^^^^^^^^^^^^^^^^^^^^^^^^^^^^^^^^^^^^^
  File "/home/kolo/Python_Projects/Product_Analyzer/venv/lib/python3.11/site-packages/quart_httpauth.py", line 180, in decorated
    return await self.auth_error_callback()
           ^^^^^^^^^^^^^^^^^^^^^^^^^^^^^^^^
  File "/home/kolo/Python_Projects/Product_Analyzer/venv/lib/python3.11/site-packages/quart_httpauth.py", line 64, in decorated
    res = await make_response(res)
          ^^^^^^^^^^^^^^^^^^^^^^^^
  File "/home/kolo/Python_Projects/Product_Analyzer/venv/lib/python3.11/site-packages/quart/helpers.py", line 71, in make_response
    return await current_app.make_response(cast(ResponseReturnValue, args))
           ^^^^^^^^^^^^^^^^^^^^^^^^^^^^^^^^^^^^^^^^^^^^^^^^^^^^^^^^^^^^^^^^
  File "/home/kolo/Python_Projects/Product_Analyzer/venv/lib/python3.11/site-packages/quart/app.py", line 1388, in make_response
    raise TypeError(f"The response value type ({type(value).__name__}) is not valid")
TypeError: The response value type (coroutine) is not valid
2024-10-11 20:35:38,232 - root - WARNING - Start Product Analyzer...



2024-10-11 20:35:38,241 - hypercorn.error - INFO - Running on http://127.0.0.1:5000 (CTRL + C to quit)



2024-10-11 20:35:53,672 - hypercorn.error - ERROR - Error in ASGI Framework


Traceback (most recent call last):
  File "/home/kolo/Python_Projects/Product_Analyzer/venv/lib/python3.11/site-packages/quart_httpauth.py", line 178, in decorated
    return await self.auth_error_callback(status)
           ^^^^^^^^^^^^^^^^^^^^^^^^^^^^^^^^^^^^^^
  File "/home/kolo/Python_Projects/Product_Analyzer/venv/lib/python3.11/site-packages/quart_httpauth.py", line 62, in decorated
    res = await self.ensure_async(f)(*args, **kwargs)
          ^^^^^^^^^^^^^^^^^^^^^^^^^^^^^^^^^^^^^^^^^^^
  File "/home/kolo/Python_Projects/Product_Analyzer/venv/lib/python3.11/site-packages/quart/utils.py", line 57, in _wrapper
    result = await loop.run_in_executor(
             ^^^^^^^^^^^^^^^^^^^^^^^^^^^
  File "/usr/lib/python3.11/concurrent/futures/thread.py", line 58, in run
    result = self.fn(*self.args, **self.kwargs)
             ^^^^^^^^^^^^^^^^^^^^^^^^^^^^^^^^^^
TypeError: unauthorized() takes 0 positional arguments but 1 was given

During handling of the above exception, another exception occurred:

Traceback (most recent call last):
  File "/home/kolo/Python_Projects/Product_Analyzer/venv/lib/python3.11/site-packages/hypercorn/asyncio/task_group.py", line 27, in _handle
    await app(scope, receive, send, sync_spawn, call_soon)
  File "/home/kolo/Python_Projects/Product_Analyzer/venv/lib/python3.11/site-packages/hypercorn/app_wrappers.py", line 34, in __call__
    await self.app(scope, receive, send)
  File "/home/kolo/Python_Projects/Product_Analyzer/venv/lib/python3.11/site-packages/quart/app.py", line 1667, in __call__
    await self.asgi_app(scope, receive, send)
  File "/home/kolo/Python_Projects/Product_Analyzer/venv/lib/python3.11/site-packages/quart/app.py", line 1693, in asgi_app
    await asgi_handler(receive, send)
  File "/home/kolo/Python_Projects/Product_Analyzer/venv/lib/python3.11/site-packages/quart/asgi.py", line 52, in __call__
    raise_task_exceptions(done)
  File "/home/kolo/Python_Projects/Product_Analyzer/venv/lib/python3.11/site-packages/quart/utils.py", line 180, in raise_task_exceptions
    raise task.exception()
  File "/home/kolo/Python_Projects/Product_Analyzer/venv/lib/python3.11/site-packages/quart/asgi.py", line 100, in handle_request
    response = await _handle_exception(self.app, error)
               ^^^^^^^^^^^^^^^^^^^^^^^^^^^^^^^^^^^^^^^^
  File "/home/kolo/Python_Projects/Product_Analyzer/venv/lib/python3.11/site-packages/quart/asgi.py", line 357, in _handle_exception
    raise error
  File "/home/kolo/Python_Projects/Product_Analyzer/venv/lib/python3.11/site-packages/quart/asgi.py", line 98, in handle_request
    response = await self.app.handle_request(request)
               ^^^^^^^^^^^^^^^^^^^^^^^^^^^^^^^^^^^^^^
  File "/home/kolo/Python_Projects/Product_Analyzer/venv/lib/python3.11/site-packages/quart/app.py", line 1407, in handle_request
    return await self.handle_exception(error)
           ^^^^^^^^^^^^^^^^^^^^^^^^^^^^^^^^^^
  File "/home/kolo/Python_Projects/Product_Analyzer/venv/lib/python3.11/site-packages/quart/app.py", line 1403, in handle_request
    return await self.full_dispatch_request(request_context)
           ^^^^^^^^^^^^^^^^^^^^^^^^^^^^^^^^^^^^^^^^^^^^^^^^^
  File "/home/kolo/Python_Projects/Product_Analyzer/venv/lib/python3.11/site-packages/quart/app.py", line 1441, in full_dispatch_request
    result = await self.handle_user_exception(error)
             ^^^^^^^^^^^^^^^^^^^^^^^^^^^^^^^^^^^^^^^
  File "/home/kolo/Python_Projects/Product_Analyzer/venv/lib/python3.11/site-packages/quart/app.py", line 1029, in handle_user_exception
    raise error
  File "/home/kolo/Python_Projects/Product_Analyzer/venv/lib/python3.11/site-packages/quart/app.py", line 1439, in full_dispatch_request
    result = await self.dispatch_request(request_context)
             ^^^^^^^^^^^^^^^^^^^^^^^^^^^^^^^^^^^^^^^^^^^^
  File "/home/kolo/Python_Projects/Product_Analyzer/venv/lib/python3.11/site-packages/quart/app.py", line 1535, in dispatch_request
    return await self.ensure_async(handler)(**request_.view_args)  # type: ignore
           ^^^^^^^^^^^^^^^^^^^^^^^^^^^^^^^^^^^^^^^^^^^^^^^^^^^^^^
  File "/home/kolo/Python_Projects/Product_Analyzer/venv/lib/python3.11/site-packages/quart_httpauth.py", line 180, in decorated
    return await self.auth_error_callback()
           ^^^^^^^^^^^^^^^^^^^^^^^^^^^^^^^^
  File "/home/kolo/Python_Projects/Product_Analyzer/venv/lib/python3.11/site-packages/quart_httpauth.py", line 64, in decorated
    res = await make_response(res)
          ^^^^^^^^^^^^^^^^^^^^^^^^
  File "/home/kolo/Python_Projects/Product_Analyzer/venv/lib/python3.11/site-packages/quart/helpers.py", line 71, in make_response
    return await current_app.make_response(cast(ResponseReturnValue, args))
           ^^^^^^^^^^^^^^^^^^^^^^^^^^^^^^^^^^^^^^^^^^^^^^^^^^^^^^^^^^^^^^^^
  File "/home/kolo/Python_Projects/Product_Analyzer/venv/lib/python3.11/site-packages/quart/app.py", line 1388, in make_response
    raise TypeError(f"The response value type ({type(value).__name__}) is not valid")
TypeError: The response value type (coroutine) is not valid
2024-10-11 20:36:41,460 - root - WARNING - Start Product Analyzer...



2024-10-11 20:36:41,470 - hypercorn.error - INFO - Running on http://127.0.0.1:5000 (CTRL + C to quit)



2024-10-11 20:36:43,855 - hypercorn.error - ERROR - Error in ASGI Framework


Traceback (most recent call last):
  File "/home/kolo/Python_Projects/Product_Analyzer/venv/lib/python3.11/site-packages/quart_httpauth.py", line 178, in decorated
    return await self.auth_error_callback(status)
           ^^^^^^^^^^^^^^^^^^^^^^^^^^^^^^^^^^^^^^
  File "/home/kolo/Python_Projects/Product_Analyzer/venv/lib/python3.11/site-packages/quart_httpauth.py", line 62, in decorated
    res = await self.ensure_async(f)(*args, **kwargs)
          ^^^^^^^^^^^^^^^^^^^^^^^^^^^^^^^^^^^^^^^^^^^
  File "/home/kolo/Python_Projects/Product_Analyzer/venv/lib/python3.11/site-packages/quart/utils.py", line 57, in _wrapper
    result = await loop.run_in_executor(
             ^^^^^^^^^^^^^^^^^^^^^^^^^^^
  File "/usr/lib/python3.11/concurrent/futures/thread.py", line 58, in run
    result = self.fn(*self.args, **self.kwargs)
             ^^^^^^^^^^^^^^^^^^^^^^^^^^^^^^^^^^
TypeError: unauthorized() takes 0 positional arguments but 1 was given

During handling of the above exception, another exception occurred:

Traceback (most recent call last):
  File "/home/kolo/Python_Projects/Product_Analyzer/venv/lib/python3.11/site-packages/hypercorn/asyncio/task_group.py", line 27, in _handle
    await app(scope, receive, send, sync_spawn, call_soon)
  File "/home/kolo/Python_Projects/Product_Analyzer/venv/lib/python3.11/site-packages/hypercorn/app_wrappers.py", line 34, in __call__
    await self.app(scope, receive, send)
  File "/home/kolo/Python_Projects/Product_Analyzer/venv/lib/python3.11/site-packages/quart/app.py", line 1667, in __call__
    await self.asgi_app(scope, receive, send)
  File "/home/kolo/Python_Projects/Product_Analyzer/venv/lib/python3.11/site-packages/quart/app.py", line 1693, in asgi_app
    await asgi_handler(receive, send)
  File "/home/kolo/Python_Projects/Product_Analyzer/venv/lib/python3.11/site-packages/quart/asgi.py", line 52, in __call__
    raise_task_exceptions(done)
  File "/home/kolo/Python_Projects/Product_Analyzer/venv/lib/python3.11/site-packages/quart/utils.py", line 180, in raise_task_exceptions
    raise task.exception()
  File "/home/kolo/Python_Projects/Product_Analyzer/venv/lib/python3.11/site-packages/quart/asgi.py", line 100, in handle_request
    response = await _handle_exception(self.app, error)
               ^^^^^^^^^^^^^^^^^^^^^^^^^^^^^^^^^^^^^^^^
  File "/home/kolo/Python_Projects/Product_Analyzer/venv/lib/python3.11/site-packages/quart/asgi.py", line 357, in _handle_exception
    raise error
  File "/home/kolo/Python_Projects/Product_Analyzer/venv/lib/python3.11/site-packages/quart/asgi.py", line 98, in handle_request
    response = await self.app.handle_request(request)
               ^^^^^^^^^^^^^^^^^^^^^^^^^^^^^^^^^^^^^^
  File "/home/kolo/Python_Projects/Product_Analyzer/venv/lib/python3.11/site-packages/quart/app.py", line 1407, in handle_request
    return await self.handle_exception(error)
           ^^^^^^^^^^^^^^^^^^^^^^^^^^^^^^^^^^
  File "/home/kolo/Python_Projects/Product_Analyzer/venv/lib/python3.11/site-packages/quart/app.py", line 1403, in handle_request
    return await self.full_dispatch_request(request_context)
           ^^^^^^^^^^^^^^^^^^^^^^^^^^^^^^^^^^^^^^^^^^^^^^^^^
  File "/home/kolo/Python_Projects/Product_Analyzer/venv/lib/python3.11/site-packages/quart/app.py", line 1441, in full_dispatch_request
    result = await self.handle_user_exception(error)
             ^^^^^^^^^^^^^^^^^^^^^^^^^^^^^^^^^^^^^^^
  File "/home/kolo/Python_Projects/Product_Analyzer/venv/lib/python3.11/site-packages/quart/app.py", line 1029, in handle_user_exception
    raise error
  File "/home/kolo/Python_Projects/Product_Analyzer/venv/lib/python3.11/site-packages/quart/app.py", line 1439, in full_dispatch_request
    result = await self.dispatch_request(request_context)
             ^^^^^^^^^^^^^^^^^^^^^^^^^^^^^^^^^^^^^^^^^^^^
  File "/home/kolo/Python_Projects/Product_Analyzer/venv/lib/python3.11/site-packages/quart/app.py", line 1535, in dispatch_request
    return await self.ensure_async(handler)(**request_.view_args)  # type: ignore
           ^^^^^^^^^^^^^^^^^^^^^^^^^^^^^^^^^^^^^^^^^^^^^^^^^^^^^^
  File "/home/kolo/Python_Projects/Product_Analyzer/venv/lib/python3.11/site-packages/quart_httpauth.py", line 180, in decorated
    return await self.auth_error_callback()
           ^^^^^^^^^^^^^^^^^^^^^^^^^^^^^^^^
  File "/home/kolo/Python_Projects/Product_Analyzer/venv/lib/python3.11/site-packages/quart_httpauth.py", line 64, in decorated
    res = await make_response(res)
          ^^^^^^^^^^^^^^^^^^^^^^^^
  File "/home/kolo/Python_Projects/Product_Analyzer/venv/lib/python3.11/site-packages/quart/helpers.py", line 71, in make_response
    return await current_app.make_response(cast(ResponseReturnValue, args))
           ^^^^^^^^^^^^^^^^^^^^^^^^^^^^^^^^^^^^^^^^^^^^^^^^^^^^^^^^^^^^^^^^
  File "/home/kolo/Python_Projects/Product_Analyzer/venv/lib/python3.11/site-packages/quart/app.py", line 1388, in make_response
    raise TypeError(f"The response value type ({type(value).__name__}) is not valid")
TypeError: The response value type (coroutine) is not valid
2024-10-11 20:37:28,396 - root - WARNING - Start Product Analyzer...



2024-10-11 20:37:28,405 - hypercorn.error - INFO - Running on http://127.0.0.1:5000 (CTRL + C to quit)



2024-10-11 20:37:30,871 - hypercorn.error - ERROR - Error in ASGI Framework


Traceback (most recent call last):
  File "/home/kolo/Python_Projects/Product_Analyzer/venv/lib/python3.11/site-packages/quart_httpauth.py", line 178, in decorated
    return await self.auth_error_callback(status)
           ^^^^^^^^^^^^^^^^^^^^^^^^^^^^^^^^^^^^^^
  File "/home/kolo/Python_Projects/Product_Analyzer/venv/lib/python3.11/site-packages/quart_httpauth.py", line 62, in decorated
    res = await self.ensure_async(f)(*args, **kwargs)
                ^^^^^^^^^^^^^^^^^^^^^^^^^^^^^^^^^^^^^
TypeError: unauthorized() takes 0 positional arguments but 1 was given

During handling of the above exception, another exception occurred:

Traceback (most recent call last):
  File "/home/kolo/Python_Projects/Product_Analyzer/venv/lib/python3.11/site-packages/hypercorn/asyncio/task_group.py", line 27, in _handle
    await app(scope, receive, send, sync_spawn, call_soon)
  File "/home/kolo/Python_Projects/Product_Analyzer/venv/lib/python3.11/site-packages/hypercorn/app_wrappers.py", line 34, in __call__
    await self.app(scope, receive, send)
  File "/home/kolo/Python_Projects/Product_Analyzer/venv/lib/python3.11/site-packages/quart/app.py", line 1667, in __call__
    await self.asgi_app(scope, receive, send)
  File "/home/kolo/Python_Projects/Product_Analyzer/venv/lib/python3.11/site-packages/quart/app.py", line 1693, in asgi_app
    await asgi_handler(receive, send)
  File "/home/kolo/Python_Projects/Product_Analyzer/venv/lib/python3.11/site-packages/quart/asgi.py", line 52, in __call__
    raise_task_exceptions(done)
  File "/home/kolo/Python_Projects/Product_Analyzer/venv/lib/python3.11/site-packages/quart/utils.py", line 180, in raise_task_exceptions
    raise task.exception()
  File "/home/kolo/Python_Projects/Product_Analyzer/venv/lib/python3.11/site-packages/quart/asgi.py", line 100, in handle_request
    response = await _handle_exception(self.app, error)
               ^^^^^^^^^^^^^^^^^^^^^^^^^^^^^^^^^^^^^^^^
  File "/home/kolo/Python_Projects/Product_Analyzer/venv/lib/python3.11/site-packages/quart/asgi.py", line 357, in _handle_exception
    raise error
  File "/home/kolo/Python_Projects/Product_Analyzer/venv/lib/python3.11/site-packages/quart/asgi.py", line 98, in handle_request
    response = await self.app.handle_request(request)
               ^^^^^^^^^^^^^^^^^^^^^^^^^^^^^^^^^^^^^^
  File "/home/kolo/Python_Projects/Product_Analyzer/venv/lib/python3.11/site-packages/quart/app.py", line 1407, in handle_request
    return await self.handle_exception(error)
           ^^^^^^^^^^^^^^^^^^^^^^^^^^^^^^^^^^
  File "/home/kolo/Python_Projects/Product_Analyzer/venv/lib/python3.11/site-packages/quart/app.py", line 1403, in handle_request
    return await self.full_dispatch_request(request_context)
           ^^^^^^^^^^^^^^^^^^^^^^^^^^^^^^^^^^^^^^^^^^^^^^^^^
  File "/home/kolo/Python_Projects/Product_Analyzer/venv/lib/python3.11/site-packages/quart/app.py", line 1441, in full_dispatch_request
    result = await self.handle_user_exception(error)
             ^^^^^^^^^^^^^^^^^^^^^^^^^^^^^^^^^^^^^^^
  File "/home/kolo/Python_Projects/Product_Analyzer/venv/lib/python3.11/site-packages/quart/app.py", line 1029, in handle_user_exception
    raise error
  File "/home/kolo/Python_Projects/Product_Analyzer/venv/lib/python3.11/site-packages/quart/app.py", line 1439, in full_dispatch_request
    result = await self.dispatch_request(request_context)
             ^^^^^^^^^^^^^^^^^^^^^^^^^^^^^^^^^^^^^^^^^^^^
  File "/home/kolo/Python_Projects/Product_Analyzer/venv/lib/python3.11/site-packages/quart/app.py", line 1535, in dispatch_request
    return await self.ensure_async(handler)(**request_.view_args)  # type: ignore
           ^^^^^^^^^^^^^^^^^^^^^^^^^^^^^^^^^^^^^^^^^^^^^^^^^^^^^^
  File "/home/kolo/Python_Projects/Product_Analyzer/venv/lib/python3.11/site-packages/quart_httpauth.py", line 180, in decorated
    return await self.auth_error_callback()
           ^^^^^^^^^^^^^^^^^^^^^^^^^^^^^^^^
  File "/home/kolo/Python_Projects/Product_Analyzer/venv/lib/python3.11/site-packages/quart_httpauth.py", line 64, in decorated
    res = await make_response(res)
          ^^^^^^^^^^^^^^^^^^^^^^^^
  File "/home/kolo/Python_Projects/Product_Analyzer/venv/lib/python3.11/site-packages/quart/helpers.py", line 71, in make_response
    return await current_app.make_response(cast(ResponseReturnValue, args))
           ^^^^^^^^^^^^^^^^^^^^^^^^^^^^^^^^^^^^^^^^^^^^^^^^^^^^^^^^^^^^^^^^
  File "/home/kolo/Python_Projects/Product_Analyzer/venv/lib/python3.11/site-packages/quart/app.py", line 1388, in make_response
    raise TypeError(f"The response value type ({type(value).__name__}) is not valid")
TypeError: The response value type (coroutine) is not valid
